<!--URDF generated by ONSHAPE BY PTC INC, 1.213-->
<robot name="root">
    <link name="body">
        <inertial>
            <mass value="2.57431" />
            <origin xyz="1.6961e-17 2.22829e-17 -0.0123125" rpy="0 -0 0" />
            <inertia ixx="0.0338994" ixy="0" ixz="0" iyy="0.0264062" iyz="0" izz="0.0588794" />
        </inertial>
        <visual>
            <origin xyz="0 0 0" rpy="0 -0 0" />
            <geometry>
                <mesh filename="package://inchworming_rover/meshes/body.stl" scale="1 1 1" />
            </geometry>
            <material name="0.615686_0.811765_0.929412_0.000000_0.000000">
                <texture />
                <color rgba="0.615686 0.811765 0.929412 1" />
            </material>
        </visual>
    </link>
    <link name="front_right_leg">
        <inertial>
            <mass value="0.178965" />
            <origin xyz="0.005 0 -0.075" rpy="0 -0 0" />
            <inertia ixx="0.000469913" ixy="0" ixz="0" iyy="0.000446836" iyz="0" izz="2.60602e-05" />
        </inertial>
        <visual>
            <origin xyz="-0.15 0.125 0.01" rpy="0 -0 0" />
            <geometry>
                <mesh filename="package://inchworming_rover/meshes/leg.stl" scale="1 1 1" />
            </geometry>
            <material name="0.231373_0.380392_0.705882_0.000000_0.000000">
                <texture />
                <color rgba="0.231373 0.380392 0.705882 1" />
            </material>
        </visual>
    </link>
    <link name="front_left_leg">
        <inertial>
            <mass value="0.178965" />
            <origin xyz="-0.005 0 -0.075" rpy="0 -0 0" />
            <inertia ixx="0.000469913" ixy="0" ixz="0" iyy="0.000446836" iyz="0" izz="2.60602e-05" />
        </inertial>
        <visual>
            <origin xyz="-0.16 0.125 0.01" rpy="0 -0 0" />
            <geometry>
                <mesh filename="package://inchworming_rover/meshes/leg.stl" scale="1 1 1" />
            </geometry>
            <material name="0.231373_0.380392_0.705882_0.000000_0.000000">
                <texture />
                <color rgba="0.231373 0.380392 0.705882 1" />
            </material>
        </visual>
    </link>
    <link name="rear_right_leg">
        <inertial>
            <mass value="0.178965" />
            <origin xyz="0.005 0 -0.075" rpy="0 -0 0" />
            <inertia ixx="0.000469913" ixy="0" ixz="0" iyy="0.000446836" iyz="0" izz="2.60602e-05" />
        </inertial>
        <visual>
            <origin xyz="-0.15 0.125 0.01" rpy="0 -0 0" />
            <geometry>
                <mesh filename="package://inchworming_rover/meshes/leg.stl" scale="1 1 1" />
            </geometry>
            <material name="0.231373_0.380392_0.705882_0.000000_0.000000">
                <texture />
                <color rgba="0.231373 0.380392 0.705882 1" />
            </material>
        </visual>
    </link>
    <link name="rear_left_leg">
        <inertial>
            <mass value="0.178965" />
            <origin xyz="-0.005 0 -0.075" rpy="0 -0 0" />
            <inertia ixx="0.000469913" ixy="0" ixz="0" iyy="0.000446836" iyz="0" izz="2.60602e-05" />
        </inertial>
        <visual>
            <origin xyz="-0.16 0.125 0.01" rpy="0 -0 0" />
            <geometry>
                <mesh filename="package://inchworming_rover/meshes/leg.stl" scale="1 1 1" />
            </geometry>
            <material name="0.231373_0.380392_0.705882_0.000000_0.000000">
                <texture />
                <color rgba="0.231373 0.380392 0.705882 1" />
            </material>
        </visual>
    </link>
    <link name="rear_right_motor">
        <inertial>
            <mass value="0.215238" />
            <origin xyz="-0.012069 0 -2.77556e-17" rpy="0 -0 0" />
            <inertia ixx="2.68352e-05" ixy="0" ixz="0" iyy="0.000266082" iyz="0" izz="0.000266082" />
        </inertial>
        <visual>
            <origin xyz="-0.15 0.125 0.16" rpy="0 -0 0" />
            <geometry>
                <mesh filename="package://inchworming_rover/meshes/motor.stl" scale="1 1 1" />
            </geometry>
            <material name="0.917647_0.917647_0.917647_0.000000_0.000000">
                <texture />
                <color rgba="0.917647 0.917647 0.917647 1" />
            </material>
        </visual>
    </link>
    <link name="front_left_motor">
        <inertial>
            <mass value="0.215238" />
            <origin xyz="-0.012069 0 -2.77556e-17" rpy="0 -0 0" />
            <inertia ixx="2.68352e-05" ixy="0" ixz="0" iyy="0.000266082" iyz="0" izz="0.000266082" />
        </inertial>
        <visual>
            <origin xyz="-0.15 0.125 0.16" rpy="0 -0 0" />
            <geometry>
                <mesh filename="package://inchworming_rover/meshes/motor.stl" scale="1 1 1" />
            </geometry>
            <material name="0.917647_0.917647_0.917647_0.000000_0.000000">
                <texture />
                <color rgba="0.917647 0.917647 0.917647 1" />
            </material>
        </visual>
    </link>
    <link name="front_right_motor">
        <inertial>
            <mass value="0.215238" />
            <origin xyz="-0.012069 0 -2.77556e-17" rpy="0 -0 0" />
            <inertia ixx="2.68352e-05" ixy="0" ixz="0" iyy="0.000266082" iyz="0" izz="0.000266082" />
        </inertial>
        <visual>
            <origin xyz="-0.15 0.125 0.16" rpy="0 -0 0" />
            <geometry>
                <mesh filename="package://inchworming_rover/meshes/motor.stl" scale="1 1 1" />
            </geometry>
            <material name="0.917647_0.917647_0.917647_0.000000_0.000000">
                <texture />
                <color rgba="0.917647 0.917647 0.917647 1" />
            </material>
        </visual>
    </link>
    <link name="rear_left_motor">
        <inertial>
            <mass value="0.215238" />
            <origin xyz="-0.012069 0 -2.77556e-17" rpy="0 -0 0" />
            <inertia ixx="2.68352e-05" ixy="0" ixz="0" iyy="0.000266082" iyz="0" izz="0.000266082" />
        </inertial>
        <visual>
            <origin xyz="-0.15 0.125 0.16" rpy="0 -0 0" />
            <geometry>
                <mesh filename="package://inchworming_rover/meshes/motor.stl" scale="1 1 1" />
            </geometry>
            <material name="0.917647_0.917647_0.917647_0.000000_0.000000">
                <texture />
                <color rgba="0.917647 0.917647 0.917647 1" />
            </material>
        </visual>
    </link>
    <link name="front_left_wheel">
        <inertial>
            <mass value="0.942478" />
            <origin xyz="-0.025 0 -2.77556e-17" rpy="0 -0 0" />
            <inertia ixx="0.00235619" ixy="0" ixz="0" iyy="0.00137445" iyz="0" izz="0.00137445" />
        </inertial>
        <visual>
            <origin xyz="-0.22 0.125 0.16" rpy="0 -0 0" />
            <geometry>
                <mesh filename="package://inchworming_rover/meshes/wheel.stl" scale="1 1 1" />
            </geometry>
            <material name="0.768627_0.886275_0.952941_0.000000_0.000000">
                <texture />
                <color rgba="0.768627 0.886275 0.952941 1" />
            </material>
        </visual>
    </link>
    <link name="rear_left_wheel">
        <inertial>
            <mass value="0.942478" />
            <origin xyz="-0.025 0 -2.77556e-17" rpy="0 -0 0" />
            <inertia ixx="0.00235619" ixy="0" ixz="0" iyy="0.00137445" iyz="0" izz="0.00137445" />
        </inertial>
        <visual>
            <origin xyz="-0.22 0.125 0.16" rpy="0 -0 0" />
            <geometry>
                <mesh filename="package://inchworming_rover/meshes/wheel.stl" scale="1 1 1" />
            </geometry>
            <material name="0.768627_0.886275_0.952941_0.000000_0.000000">
                <texture />
                <color rgba="0.768627 0.886275 0.952941 1" />
            </material>
        </visual>
    </link>
    <link name="front_right_wheel">
        <inertial>
            <mass value="0.942478" />
            <origin xyz="0.025 0 -2.77556e-17" rpy="0 -0 0" />
            <inertia ixx="0.00235619" ixy="0" ixz="0" iyy="0.00137445" iyz="0" izz="0.00137445" />
        </inertial>
        <visual>
            <origin xyz="-0.17 0.125 0.16" rpy="0 -0 0" />
            <geometry>
                <mesh filename="package://inchworming_rover/meshes/wheel.stl" scale="1 1 1" />
            </geometry>
            <material name="0.768627_0.886275_0.952941_0.000000_0.000000">
                <texture />
                <color rgba="0.768627 0.886275 0.952941 1" />
            </material>
        </visual>
    </link>
    <link name="rear_right_wheel">
        <inertial>
            <mass value="0.942478" />
            <origin xyz="0.025 0 -2.77556e-17" rpy="0 -0 0" />
            <inertia ixx="0.00235619" ixy="0" ixz="0" iyy="0.00137445" iyz="0" izz="0.00137445" />
        </inertial>
        <visual>
            <origin xyz="-0.17 0.125 0.16" rpy="0 -0 0" />
            <geometry>
                <mesh filename="package://inchworming_rover/meshes/wheel.stl" scale="1 1 1" />
            </geometry>
            <material name="0.768627_0.886275_0.952941_0.000000_0.000000">
                <texture />
                <color rgba="0.768627 0.886275 0.952941 1" />
            </material>
        </visual>
    </link>
    <joint name="front_left_leg_joint" type="revolute">
        <origin xyz="0.16 -0.125 -0.01" rpy="0 0 0" />
        <axis xyz="1 0 0" />
        <parent link="body" />
        <child link="front_left_leg" />
        <limit lower="-1.57" upper="0" effort="10.0" velocity="10.0"/>
    </joint>
    <joint name="front_left_motor_fasten_0" type="fixed">
        <origin xyz="-0.01 0 -0.15" rpy="0 0 0" />
        <axis xyz="1 0 0" />
        <parent link="front_left_leg" />
        <child link="front_left_motor" />
    </joint>
    <joint name="front_left_wheel_joint" type="continuous">
        <origin xyz="0.07 0 0" rpy="0 0 0" />
        <axis xyz="1 0 0" />
        <parent link="front_left_motor" />
        <child link="front_left_wheel" />
    </joint>
    <joint name="front_right_leg_joint" type="revolute">
        <origin xyz="-0.16 -0.125 -0.01" rpy="0 0 0" />
        <axis xyz="-1 0 0" />
        <parent link="body" />
        <child link="front_right_leg" />
        <limit lower="0" upper="1.57" effort="10.0" velocity="10.0"/>
    </joint>
    <joint name="front_right_motor_fasten" type="fixed">
        <origin xyz="0.01 0 -0.15" rpy="0 0 3.14159" />
        <axis xyz="1 0 0" />
        <parent link="front_right_leg" />
        <child link="front_right_motor" />
    </joint>
    <joint name="front_right_wheel_joint" type="continuous">
        <origin xyz="0.07 0 0" rpy="0 0 3.14159" />
        <axis xyz="-1 0 0" />
        <parent link="front_right_motor" />
        <child link="front_right_wheel" />
    </joint>
    <joint name="rear_left_leg_joint" type="revolute">
        <origin xyz="0.16 0.125 -0.01" rpy="0 0 0" />
        <axis xyz="1 0 0" />
        <parent link="body" />
        <child link="rear_left_leg" />
        <limit lower="0" upper="1.57" effort="10.0" velocity="10.0"/>
    </joint>
    <joint name="rear_left_motor_fasten" type="fixed">
        <origin xyz="-0.01 0 -0.15" rpy="0 -0 0" />
        <axis xyz="-1 0 0" />
        <parent link="rear_left_leg" />
        <child link="rear_left_motor" />
    </joint>
    <joint name="rear_left_wheel_joint" type="continuous">
        <origin xyz="0.07 0 0" rpy="0 0 0" />
        <axis xyz="1 0 0" />
        <parent link="rear_left_motor" />
        <child link="rear_left_wheel" />
    </joint>
    <joint name="rear_right_leg_joint" type="revolute">
        <origin xyz="-0.16 0.125 -0.01" rpy="0 0 0" />
        <axis xyz="-1 0 0" />
        <parent link="body" />
        <child link="rear_right_leg" />
        <limit lower="-1.57" upper="0" effort="10.0" velocity="10.0"/>
    </joint>
    <joint name="rear_right_motor_fasten" type="fixed">
        <origin xyz="0.01 0 -0.15" rpy="0 0 3.14159" />
        <axis xyz="1 0 0" />
        <parent link="rear_right_leg" />
        <child link="rear_right_motor" />
    </joint>
    <joint name="rear_right_wheel_joint" type="continuous">
        <origin xyz="0.07 0 0" rpy="0 0 -3.14159" />
        <axis xyz="-1 0 0" />
        <parent link="rear_right_motor" />
        <child link="rear_right_wheel" />
    </joint>
</robot>
